[31m[1mERROR   [0m asyncio:base_events.py:1771 Exception in callback SyncBase._sync.<locals>.<lambda>(<Task cancell...twork.py:394>>) at /Library/Frameworks/Python.framework/Versions/3.11/lib/python3.11/site-packages/playwright/_impl/_sync_base.py:105
handle: <Handle SyncBase._sync.<locals>.<lambda>(<Task cancell...twork.py:394>>) at /Library/Frameworks/Python.framework/Versions/3.11/lib/python3.11/site-packages/playwright/_impl/_sync_base.py:105>
Traceback (most recent call last):
  File "/Library/Frameworks/Python.framework/Versions/3.11/lib/python3.11/asyncio/events.py", line 80, in _run
    self._context.run(self._callback, *self._args)
  File "/Library/Frameworks/Python.framework/Versions/3.11/lib/python3.11/site-packages/playwright/_impl/_sync_base.py", line 105, in <lambda>
    task.add_done_callback(lambda _: g_self.switch())
                                     ^^^^^^^^^^^^^^^
  File "/Library/Frameworks/Python.framework/Versions/3.11/lib/python3.11/site-packages/playwright/_impl/_helper.py", line 281, in impl
    result = cast(
             ^^^^^
  File "/Library/Frameworks/Python.framework/Versions/3.11/lib/python3.11/site-packages/playwright/_impl/_impl_to_api_mapping.py", line 123, in wrapper_func
    return handler(
           ^^^^^^^^
  File "/Users/shiva/GitHub Projects/Playwright-tests/models/navigate.py", line 8, in rout_intercept
    return route.continue_()
           ^^^^^^^^^^^^^^^^^
  File "/Library/Frameworks/Python.framework/Versions/3.11/lib/python3.11/site-packages/playwright/sync_api/_generated.py", line 1015, in continue_
    self._sync(
  File "/Library/Frameworks/Python.framework/Versions/3.11/lib/python3.11/site-packages/playwright/_impl/_sync_base.py", line 109, in _sync
    return task.result()
           ^^^^^^^^^^^^^
  File "/Library/Frameworks/Python.framework/Versions/3.11/lib/python3.11/site-packages/playwright/_impl/_network.py", line 404, in continue_
    await self._internal_continue()
  File "/Library/Frameworks/Python.framework/Versions/3.11/lib/python3.11/site-packages/playwright/_impl/_network.py", line 426, in continue_route
    await self._connection.wrap_api_call(
  File "/Library/Frameworks/Python.framework/Versions/3.11/lib/python3.11/site-packages/playwright/_impl/_connection.py", line 482, in wrap_api_call
    return await cb()
           ^^^^^^^^^^
  File "/Library/Frameworks/Python.framework/Versions/3.11/lib/python3.11/site-packages/playwright/_impl/_network.py", line 457, in _race_with_page_close
    await asyncio.wait(
  File "/Library/Frameworks/Python.framework/Versions/3.11/lib/python3.11/asyncio/tasks.py", line 418, in wait
    return await _wait(fs, timeout, return_when, loop)
           ^^^^^^^^^^^^^^^^^^^^^^^^^^^^^^^^^^^^^^^^^^^
  File "/Library/Frameworks/Python.framework/Versions/3.11/lib/python3.11/asyncio/tasks.py", line 525, in _wait
    await waiter
asyncio.exceptions.CancelledError
[31m[1mERROR   [0m asyncio:base_events.py:1771 Exception in callback SyncBase._sync.<locals>.<lambda>(<Task cancell...twork.py:394>>) at /Library/Frameworks/Python.framework/Versions/3.11/lib/python3.11/site-packages/playwright/_impl/_sync_base.py:105
handle: <Handle SyncBase._sync.<locals>.<lambda>(<Task cancell...twork.py:394>>) at /Library/Frameworks/Python.framework/Versions/3.11/lib/python3.11/site-packages/playwright/_impl/_sync_base.py:105>
Traceback (most recent call last):
  File "/Library/Frameworks/Python.framework/Versions/3.11/lib/python3.11/asyncio/events.py", line 80, in _run
    self._context.run(self._callback, *self._args)
  File "/Library/Frameworks/Python.framework/Versions/3.11/lib/python3.11/site-packages/playwright/_impl/_sync_base.py", line 105, in <lambda>
    task.add_done_callback(lambda _: g_self.switch())
                                     ^^^^^^^^^^^^^^^
  File "/Library/Frameworks/Python.framework/Versions/3.11/lib/python3.11/site-packages/playwright/_impl/_helper.py", line 281, in impl
    result = cast(
             ^^^^^
  File "/Library/Frameworks/Python.framework/Versions/3.11/lib/python3.11/site-packages/playwright/_impl/_impl_to_api_mapping.py", line 123, in wrapper_func
    return handler(
           ^^^^^^^^
  File "/Users/shiva/GitHub Projects/Playwright-tests/models/navigate.py", line 8, in rout_intercept
    return route.continue_()
           ^^^^^^^^^^^^^^^^^
  File "/Library/Frameworks/Python.framework/Versions/3.11/lib/python3.11/site-packages/playwright/sync_api/_generated.py", line 1015, in continue_
    self._sync(
  File "/Library/Frameworks/Python.framework/Versions/3.11/lib/python3.11/site-packages/playwright/_impl/_sync_base.py", line 109, in _sync
    return task.result()
           ^^^^^^^^^^^^^
  File "/Library/Frameworks/Python.framework/Versions/3.11/lib/python3.11/site-packages/playwright/_impl/_network.py", line 404, in continue_
    await self._internal_continue()
  File "/Library/Frameworks/Python.framework/Versions/3.11/lib/python3.11/site-packages/playwright/_impl/_network.py", line 426, in continue_route
    await self._connection.wrap_api_call(
  File "/Library/Frameworks/Python.framework/Versions/3.11/lib/python3.11/site-packages/playwright/_impl/_connection.py", line 482, in wrap_api_call
    return await cb()
           ^^^^^^^^^^
  File "/Library/Frameworks/Python.framework/Versions/3.11/lib/python3.11/site-packages/playwright/_impl/_network.py", line 457, in _race_with_page_close
    await asyncio.wait(
  File "/Library/Frameworks/Python.framework/Versions/3.11/lib/python3.11/asyncio/tasks.py", line 418, in wait
    return await _wait(fs, timeout, return_when, loop)
           ^^^^^^^^^^^^^^^^^^^^^^^^^^^^^^^^^^^^^^^^^^^
  File "/Library/Frameworks/Python.framework/Versions/3.11/lib/python3.11/asyncio/tasks.py", line 525, in _wait
    await waiter
asyncio.exceptions.CancelledError
[31m[1mERROR   [0m asyncio:base_events.py:1771 Exception in callback SyncBase._sync.<locals>.<lambda>(<Task cancell...twork.py:394>>) at /Library/Frameworks/Python.framework/Versions/3.11/lib/python3.11/site-packages/playwright/_impl/_sync_base.py:105
handle: <Handle SyncBase._sync.<locals>.<lambda>(<Task cancell...twork.py:394>>) at /Library/Frameworks/Python.framework/Versions/3.11/lib/python3.11/site-packages/playwright/_impl/_sync_base.py:105>
Traceback (most recent call last):
  File "/Library/Frameworks/Python.framework/Versions/3.11/lib/python3.11/asyncio/events.py", line 80, in _run
    self._context.run(self._callback, *self._args)
  File "/Library/Frameworks/Python.framework/Versions/3.11/lib/python3.11/site-packages/playwright/_impl/_sync_base.py", line 105, in <lambda>
    task.add_done_callback(lambda _: g_self.switch())
                                     ^^^^^^^^^^^^^^^
  File "/Library/Frameworks/Python.framework/Versions/3.11/lib/python3.11/site-packages/playwright/_impl/_helper.py", line 281, in impl
    result = cast(
             ^^^^^
  File "/Library/Frameworks/Python.framework/Versions/3.11/lib/python3.11/site-packages/playwright/_impl/_impl_to_api_mapping.py", line 123, in wrapper_func
    return handler(
           ^^^^^^^^
  File "/Users/shiva/GitHub Projects/Playwright-tests/models/navigate.py", line 8, in rout_intercept
    return route.continue_()
           ^^^^^^^^^^^^^^^^^
  File "/Library/Frameworks/Python.framework/Versions/3.11/lib/python3.11/site-packages/playwright/sync_api/_generated.py", line 1015, in continue_
    self._sync(
  File "/Library/Frameworks/Python.framework/Versions/3.11/lib/python3.11/site-packages/playwright/_impl/_sync_base.py", line 109, in _sync
    return task.result()
           ^^^^^^^^^^^^^
  File "/Library/Frameworks/Python.framework/Versions/3.11/lib/python3.11/site-packages/playwright/_impl/_network.py", line 404, in continue_
    await self._internal_continue()
  File "/Library/Frameworks/Python.framework/Versions/3.11/lib/python3.11/site-packages/playwright/_impl/_network.py", line 426, in continue_route
    await self._connection.wrap_api_call(
  File "/Library/Frameworks/Python.framework/Versions/3.11/lib/python3.11/site-packages/playwright/_impl/_connection.py", line 482, in wrap_api_call
    return await cb()
           ^^^^^^^^^^
  File "/Library/Frameworks/Python.framework/Versions/3.11/lib/python3.11/site-packages/playwright/_impl/_network.py", line 457, in _race_with_page_close
    await asyncio.wait(
  File "/Library/Frameworks/Python.framework/Versions/3.11/lib/python3.11/asyncio/tasks.py", line 418, in wait
    return await _wait(fs, timeout, return_when, loop)
           ^^^^^^^^^^^^^^^^^^^^^^^^^^^^^^^^^^^^^^^^^^^
  File "/Library/Frameworks/Python.framework/Versions/3.11/lib/python3.11/asyncio/tasks.py", line 525, in _wait
    await waiter
asyncio.exceptions.CancelledError
[31m[1mERROR   [0m asyncio:base_events.py:1771 Exception in callback SyncBase._sync.<locals>.<lambda>(<Task cancell...twork.py:394>>) at /Library/Frameworks/Python.framework/Versions/3.11/lib/python3.11/site-packages/playwright/_impl/_sync_base.py:105
handle: <Handle SyncBase._sync.<locals>.<lambda>(<Task cancell...twork.py:394>>) at /Library/Frameworks/Python.framework/Versions/3.11/lib/python3.11/site-packages/playwright/_impl/_sync_base.py:105>
Traceback (most recent call last):
  File "/Library/Frameworks/Python.framework/Versions/3.11/lib/python3.11/asyncio/events.py", line 80, in _run
    self._context.run(self._callback, *self._args)
  File "/Library/Frameworks/Python.framework/Versions/3.11/lib/python3.11/site-packages/playwright/_impl/_sync_base.py", line 105, in <lambda>
    task.add_done_callback(lambda _: g_self.switch())
                                     ^^^^^^^^^^^^^^^
  File "/Library/Frameworks/Python.framework/Versions/3.11/lib/python3.11/site-packages/playwright/_impl/_helper.py", line 281, in impl
    result = cast(
             ^^^^^
  File "/Library/Frameworks/Python.framework/Versions/3.11/lib/python3.11/site-packages/playwright/_impl/_impl_to_api_mapping.py", line 123, in wrapper_func
    return handler(
           ^^^^^^^^
  File "/Users/shiva/GitHub Projects/Playwright-tests/models/navigate.py", line 8, in rout_intercept
    return route.continue_()
           ^^^^^^^^^^^^^^^^^
  File "/Library/Frameworks/Python.framework/Versions/3.11/lib/python3.11/site-packages/playwright/sync_api/_generated.py", line 1015, in continue_
    self._sync(
  File "/Library/Frameworks/Python.framework/Versions/3.11/lib/python3.11/site-packages/playwright/_impl/_sync_base.py", line 109, in _sync
    return task.result()
           ^^^^^^^^^^^^^
  File "/Library/Frameworks/Python.framework/Versions/3.11/lib/python3.11/site-packages/playwright/_impl/_network.py", line 404, in continue_
    await self._internal_continue()
  File "/Library/Frameworks/Python.framework/Versions/3.11/lib/python3.11/site-packages/playwright/_impl/_network.py", line 426, in continue_route
    await self._connection.wrap_api_call(
  File "/Library/Frameworks/Python.framework/Versions/3.11/lib/python3.11/site-packages/playwright/_impl/_connection.py", line 482, in wrap_api_call
    return await cb()
           ^^^^^^^^^^
  File "/Library/Frameworks/Python.framework/Versions/3.11/lib/python3.11/site-packages/playwright/_impl/_network.py", line 457, in _race_with_page_close
    await asyncio.wait(
  File "/Library/Frameworks/Python.framework/Versions/3.11/lib/python3.11/asyncio/tasks.py", line 418, in wait
    return await _wait(fs, timeout, return_when, loop)
           ^^^^^^^^^^^^^^^^^^^^^^^^^^^^^^^^^^^^^^^^^^^
  File "/Library/Frameworks/Python.framework/Versions/3.11/lib/python3.11/asyncio/tasks.py", line 525, in _wait
    await waiter
asyncio.exceptions.CancelledError
[31m[1mERROR   [0m asyncio:base_events.py:1771 Exception in callback SyncBase._sync.<locals>.<lambda>(<Task cancell...twork.py:394>>) at /Library/Frameworks/Python.framework/Versions/3.11/lib/python3.11/site-packages/playwright/_impl/_sync_base.py:105
handle: <Handle SyncBase._sync.<locals>.<lambda>(<Task cancell...twork.py:394>>) at /Library/Frameworks/Python.framework/Versions/3.11/lib/python3.11/site-packages/playwright/_impl/_sync_base.py:105>
Traceback (most recent call last):
  File "/Library/Frameworks/Python.framework/Versions/3.11/lib/python3.11/asyncio/events.py", line 80, in _run
    self._context.run(self._callback, *self._args)
  File "/Library/Frameworks/Python.framework/Versions/3.11/lib/python3.11/site-packages/playwright/_impl/_sync_base.py", line 105, in <lambda>
    task.add_done_callback(lambda _: g_self.switch())
                                     ^^^^^^^^^^^^^^^
  File "/Library/Frameworks/Python.framework/Versions/3.11/lib/python3.11/site-packages/playwright/_impl/_helper.py", line 281, in impl
    result = cast(
             ^^^^^
  File "/Library/Frameworks/Python.framework/Versions/3.11/lib/python3.11/site-packages/playwright/_impl/_impl_to_api_mapping.py", line 123, in wrapper_func
    return handler(
           ^^^^^^^^
  File "/Users/shiva/GitHub Projects/Playwright-tests/models/navigate.py", line 8, in rout_intercept
    return route.continue_()
           ^^^^^^^^^^^^^^^^^
  File "/Library/Frameworks/Python.framework/Versions/3.11/lib/python3.11/site-packages/playwright/sync_api/_generated.py", line 1015, in continue_
    self._sync(
  File "/Library/Frameworks/Python.framework/Versions/3.11/lib/python3.11/site-packages/playwright/_impl/_sync_base.py", line 109, in _sync
    return task.result()
           ^^^^^^^^^^^^^
  File "/Library/Frameworks/Python.framework/Versions/3.11/lib/python3.11/site-packages/playwright/_impl/_network.py", line 404, in continue_
    await self._internal_continue()
  File "/Library/Frameworks/Python.framework/Versions/3.11/lib/python3.11/site-packages/playwright/_impl/_network.py", line 426, in continue_route
    await self._connection.wrap_api_call(
  File "/Library/Frameworks/Python.framework/Versions/3.11/lib/python3.11/site-packages/playwright/_impl/_connection.py", line 482, in wrap_api_call
    return await cb()
           ^^^^^^^^^^
  File "/Library/Frameworks/Python.framework/Versions/3.11/lib/python3.11/site-packages/playwright/_impl/_network.py", line 457, in _race_with_page_close
    await asyncio.wait(
  File "/Library/Frameworks/Python.framework/Versions/3.11/lib/python3.11/asyncio/tasks.py", line 418, in wait
    return await _wait(fs, timeout, return_when, loop)
           ^^^^^^^^^^^^^^^^^^^^^^^^^^^^^^^^^^^^^^^^^^^
  File "/Library/Frameworks/Python.framework/Versions/3.11/lib/python3.11/asyncio/tasks.py", line 525, in _wait
    await waiter
asyncio.exceptions.CancelledError
[31m[1mERROR   [0m asyncio:base_events.py:1771 Exception in callback SyncBase._sync.<locals>.<lambda>(<Task cancell...twork.py:394>>) at /Library/Frameworks/Python.framework/Versions/3.11/lib/python3.11/site-packages/playwright/_impl/_sync_base.py:105
handle: <Handle SyncBase._sync.<locals>.<lambda>(<Task cancell...twork.py:394>>) at /Library/Frameworks/Python.framework/Versions/3.11/lib/python3.11/site-packages/playwright/_impl/_sync_base.py:105>
Traceback (most recent call last):
  File "/Library/Frameworks/Python.framework/Versions/3.11/lib/python3.11/asyncio/events.py", line 80, in _run
    self._context.run(self._callback, *self._args)
  File "/Library/Frameworks/Python.framework/Versions/3.11/lib/python3.11/site-packages/playwright/_impl/_sync_base.py", line 105, in <lambda>
    task.add_done_callback(lambda _: g_self.switch())
                                     ^^^^^^^^^^^^^^^
  File "/Library/Frameworks/Python.framework/Versions/3.11/lib/python3.11/site-packages/playwright/_impl/_helper.py", line 281, in impl
    result = cast(
             ^^^^^
  File "/Library/Frameworks/Python.framework/Versions/3.11/lib/python3.11/site-packages/playwright/_impl/_impl_to_api_mapping.py", line 123, in wrapper_func
    return handler(
           ^^^^^^^^
  File "/Users/shiva/GitHub Projects/Playwright-tests/models/navigate.py", line 8, in rout_intercept
    return route.continue_()
           ^^^^^^^^^^^^^^^^^
  File "/Library/Frameworks/Python.framework/Versions/3.11/lib/python3.11/site-packages/playwright/sync_api/_generated.py", line 1015, in continue_
    self._sync(
  File "/Library/Frameworks/Python.framework/Versions/3.11/lib/python3.11/site-packages/playwright/_impl/_sync_base.py", line 109, in _sync
    return task.result()
           ^^^^^^^^^^^^^
  File "/Library/Frameworks/Python.framework/Versions/3.11/lib/python3.11/site-packages/playwright/_impl/_network.py", line 404, in continue_
    await self._internal_continue()
  File "/Library/Frameworks/Python.framework/Versions/3.11/lib/python3.11/site-packages/playwright/_impl/_network.py", line 426, in continue_route
    await self._connection.wrap_api_call(
  File "/Library/Frameworks/Python.framework/Versions/3.11/lib/python3.11/site-packages/playwright/_impl/_connection.py", line 482, in wrap_api_call
    return await cb()
           ^^^^^^^^^^
  File "/Library/Frameworks/Python.framework/Versions/3.11/lib/python3.11/site-packages/playwright/_impl/_network.py", line 457, in _race_with_page_close
    await asyncio.wait(
  File "/Library/Frameworks/Python.framework/Versions/3.11/lib/python3.11/asyncio/tasks.py", line 418, in wait
    return await _wait(fs, timeout, return_when, loop)
           ^^^^^^^^^^^^^^^^^^^^^^^^^^^^^^^^^^^^^^^^^^^
  File "/Library/Frameworks/Python.framework/Versions/3.11/lib/python3.11/asyncio/tasks.py", line 525, in _wait
    await waiter
asyncio.exceptions.CancelledError